Workbook

Sheet F5.1
B1: F5.1 - KAREN T. / MADONNA H.
B2: Block 1 - Day 1
B3: Time | C3: Game | E3: Location | F3: Point Deduction
B4: 0.45833333 | C4: Big Mac | E4: Football Field | F4: 0
B5: 0.47916667 | C5: Talk | E5: Main Hall | F5: 0
B6: 0.5 | C6: Cone Memory | E6: Court | F6: 0
B7: 0.51388889 | C7: Chubby Bunny | E7: Pool | F7: 0
B8: 0.52777778 | C8: Scale | E8: Terrace | F8: 0
B9: 0.54166667 | C9: END OF BLOCK
B10: Block 2 - Day 1
B11: Time | C11: Game | E11: Location | F11: Point Deduction
B12: 0.70833333 | C12: Bible Whispers | E12: Pool | F12: 0
B13: 0.72222222 | C13: Lift | E13: Terrace | F13: 0
B14: 0.73611111 | C14: Puzzle | E14: Court | F14: 0
B15: 0.75 | C15: Talk | E15: Main Hall | F15: 0
B16: 0.77083333 | C16: Cheesy Strings | E16: Football Field | F16: 0
B17: 0.79166667 | C17: END OF BLOCK
B18: Block 3 - Day 1
B19: Time | C19: Game | E19: Location | F19: Point Deduction
B20: 0.80208333 | C20: Talk 1 | D20: Big Bucket 1 | E20: Main Hall / Football Field | F20: 0 | H20: 1. Football Field
B21: 0.82291667 | C21: Big Bucket 1 | D21: Talk 1 | E21: Football Field / Main Hall | F21: 0 | H21: 2. Terrace
B22: 0.84375 | C22: END OF BLOCK | H22: 3. Court
B23: Block 4 - Day 2 | H23: 4. Pool
B24: Time | C24: Game | E24: Location | F24: Point Deduction | H24: 5. Roof
B25: 0.41666667 | C25: Golden Snitch 1 | E25: Football Field | F25: 0 | H25: MH = Main Hall
B26: 0.4375 | C26: Nadala+ 1 | E26: Roof | F26: 0
B27: 0.45833333 | C27: Talk 1 | E27: Main Hall 1 | F27: 0
B28: 0.47916667 | C28: Balloon Darts 1 | E28: Court | F28: 0
B29: 0.5 | C29: END OF BLOCK
E30: Total Deduction: | F30: =SUM(F4:F8,F12:F16,F20:F21,F25:F28) -> 0

Sheet F5.2
B1: F5.2 - SHADY S. / MARY F.
B2: Block 1 - Day 1
B3: Time | C3: Game | E3: Location | F3: Point Deduction
B4: 0.45833333 | C4: Talk | E4: Main Hall | F4: 0
B5: 0.47916667 | C5: Big Mac | E5: Football Field | F5: 0
B6: 0.5 | C6: Scale | E6: Terrace | F6: 0
B7: 0.51388889 | C7: Cone Memory | E7: Court | F7: 0
B8: 0.52777778 | C8: Chubby Bunny | E8: Pool | F8: 0
B9: 0.54166667 | C9: END OF BLOCK
B10: Block 2 - Day 1
B11: Time | C11: Game | E11: Location | F11: Point Deduction
B12: 0.70833333 | C12: Puzzle | E12: Court | F12: 0
B13: 0.72222222 | C13: Bible Whispers | E13: Pool | F13: 0
B14: 0.73611111 | C14: Lift | E14: Terrace | F14: 0
B15: 0.75 | C15: Talk | D15: Cheesy Strings | E15: Main Hall / Football Field | F15: 0
B16: 0.77083333 | C16: Cheesy Strings | D16: Talk | E16: Football Field / Main Hall | F16: 0
B17: 0.79166667 | C17: END OF BLOCK
B18: Block 3 - Day 1
B19: Time | C19: Game | E19: Location | F19: Point Deduction
B20: 0.80208333 | C20: Talk 1 | E20: Main Hall 1 | F20: 0 | H20: 1. Football Field
B21: 0.82291667 | C21: Big Bucket 1 | E21: Football Field 1 | F21: 0 | H21: 2. Terrace
B22: 0.84375 | C22: END OF BLOCK | H22: 3. Court
B23: Block 4 - Day 2 | H23: 4. Pool
B24: Time | C24: Game | E24: Location | F24: Point Deduction | H24: 5. Roof
B25: 0.41666667 | C25: Nadala+ 1 | E25: Roof | F25: 0 | H25: MH = Main Hall
B26: 0.4375 | C26: Talk 1 | E26: Main Hall 1 | F26: 0
B27: 0.45833333 | C27: Balloon Darts 1 | E27: Court | F27: 0
B28: 0.47916667 | C28: Golden Snitch 1 | E28: Football Field | F28: 0
B29: 0.5 | C29: END OF BLOCK
E30: Total Deduction: | F30: =SUM(F4:F8,F12:F16,F20:F21,F25:F28) -> 0

Sheet F5.3
B1: F5.3 - KIRMINA S. / JOHN A.
B2: Block 1 - Day 1
B3: Time | C3: Game | E3: Location | F3: Point Deduction
B4: 0.45833333 | C4: Talk | D4: Big Mac | E4: Main Hall / Football Field | F4: 0
B5: 0.47916667 | C5: Big Mac | D5: Talk | E5: Football Field / Main Hall | F5: 0
B6: 0.5 | C6: Chubby Bunny | E6: Pool | F6: 0
B7: 0.51388889 | C7: Scale | E7: Terrace | F7: 0
B8: 0.52777778 | C8: Cone Memory | E8: Court | F8: 0
B9: 0.54166667 | C9: END OF BLOCK
B10: Block 2 - Day 1
B11: Time | C11: Game | E11: Location | F11: Point Deduction
B12: 0.70833333 | C12: Lift | E12: Terrace | F12: 0
B13: 0.72222222 | C13: Puzzle | E13: Court | F13: 0
B14: 0.73611111 | C14: Bible Whispers | E14: Pool | F14: 0
B15: 0.75 | C15: Cheesy Strings | E15: Football Field | F15: 0
B16: 0.77083333 | C16: Talk | E16: Main Hall | F16: 0
B17: 0.79166667 | C17: END OF BLOCK
B18: Block 3 - Day 1
B19: Time | C19: Game | E19: Location | F19: Point Deduction
B20: 0.80208333 | C20: Talk 1 | E20: Main Hall 1 | F20: 0 | H20: 1. Football Field
B21: 0.82291667 | C21: Big Bucket 1 | E21: Football Field 1 | F21: 0 | H21: 2. Terrace
B22: 0.84375 | C22: END OF BLOCK | H22: 3. Court
B23: Block 4 - Day 2 | H23: 4. Pool
B24: Time | C24: Game | E24: Location | F24: Point Deduction | H24: 5. Roof
B25: 0.41666667 | C25: Talk 1 | E25: Main Hall 1 | F25: 0 | H25: MH = Main Hall
B26: 0.4375 | C26: Balloon Darts 1 | E26: Court | F26: 0
B27: 0.45833333 | C27: Golden Snitch 1 | E27: Football Field | F27: 0
B28: 0.47916667 | C28: Nadala+ 1 | E28: Roof | F28: 0
B29: 0.5 | C29: END OF BLOCK
E30: Total Deduction: | F30: =SUM(F4:F8,F12:F16,F20:F21,F25:F28) -> 0

Sheet F6.1
B1: F6.1 - SHERRY W. / KIRO
B2: Block 1 - Day 1
B3: Time | C3: Game | E3: Location | F3: Point Deduction
B4: 0.45833333 | C4: Cone Memory | E4: Court | F4: 0
B5: 0.47222222 | C5: Chubby Bunny | E5: Pool | F5: 0
B6: 0.98611111 | C6: Scale | E6: Terrace | F6: 0
B7: 0.5 | C7: Big Mac | E7: Football Field | F7: 0
B8: 0.52083333 | C8: Talk | E8: Main Hall | F8: 0
B9: 0.54166667 | C9: END OF BLOCK
B10: Block 2 - Day 1
B11: Time | C11: Game | E11: Location | F11: Point Deduction
B12: 0.70833333 | C12: Talk | E12: Main Hall | F12: 0
B13: 0.72916667 | C13: Cheesy Strings | E13: Football Field | F13: 0
B14: 0.75 | C14: Bible Whispers | E14: Pool | F14: 0
B15: 0.76388889 | C15: Lift | E15: Terrace | F15: 0
B16: 0.77777778 | C16: Puzzle | E16: Court | F16: 0
B17: 0.79166667 | C17: END OF BLOCK
B18: Block 3 - Day 1
B19: Time | C19: Game | E19: Location | F19: Point Deduction
B20: 0.80208333 | C20: Talk 2 | D20: Big Bucket 2 | E20: Main Hall / Football Field | F20: 0 | H20: 1. Football Field
B21: 0.82291667 | C21: Big Bucket 2 | D21: Talk 2 | E21: Football Field / Main Hall | F21: 0 | H21: 2. Terrace
B22: 0.84375 | C22: END OF BLOCK | H22: 3. Court
B23: Block 4 - Day 2 | H23: 4. Pool
B24: Time | C24: Game | E24: Location | F24: Point Deduction | H24: 5. Roof
B25: 0.41666667 | C25: Golden Snitch 2 | E25: Football Field | F25: 0 | H25: MH = Main Hall
B26: 0.4375 | C26: Nadala+ 2 | E26: Roof | F26: 0
B27: 0.45833333 | C27: Talk 2 | E27: ? | F27: 0
B28: 0.47916667 | C28: Balloon Darts 2 | E28: Court | F28: 0
B29: 0.5 | C29: END OF BLOCK
E30: Total Deduction: | F30: =SUM(F4:F8,F12:F16,F20:F21,F25:F28) -> 0

Sheet F6.2
B1: F6.2 - ROBERTO / MICHAEL H.
B2: Block 1 - Day 1
B3: Time | C3: Game | E3: Location | F3: Point Deduction
B4: 0.45833333 | C4: Scale | E4: Terrace | F4: 0
B5: 0.47222222 | C5: Cone Memory | E5: Court | F5: 0
B6: 0.98611111 | C6: Chubby Bunny | E6: Pool | F6: 0
B7: 0.5 | C7: Talk | E7: Main Hall | F7: 0
B8: 0.52083333 | C8: Big Mac | E8: Football Field | F8: 0
B9: 0.54166667 | C9: END OF BLOCK
B10: Block 2 - Day 1
B11: Time | C11: Game | E11: Location | F11: Point Deduction
B12: 0.70833333 | C12: Talk | D12: Cheesy Strings | E12: Main Hall / Football Field | F12: 0
B13: 0.72916667 | C13: Cheesy Strings | D13: Talk | E13: Football Field / Main Hall | F13: 0
B14: 0.75 | C14: Puzzle | E14: Court | F14: 0
B15: 0.76388889 | C15: Bible Whispers | E15: Pool | F15: 0
B16: 0.77777778 | C16: Lift | E16: Terrace | F16: 0
B17: 0.79166667 | C17: END OF BLOCK
B18: Block 3 - Day 1
B19: Time | C19: Game | E19: Location | F19: Point Deduction
B20: 0.80208333 | C20: Big Bucket 2 | E20: Football Field | F20: 0 | H20: 1. Football Field
B21: 0.82291667 | C21: Talk 2 | E21: Main Hall | F21: 0 | H21: 2. Terrace
B22: 0.84375 | C22: END OF BLOCK | H22: 3. Court
B23: Block 4 - Day 2 | H23: 4. Pool
B24: Time | C24: Game | E24: Location | F24: Point Deduction | H24: 5. Roof
B25: 0.41666667 | C25: Nadala+ 2 | E25: Roof | F25: 0 | H25: MH = Main Hall
B26: 0.4375 | C26: Talk 2 | E26: ? | F26: 0
B27: 0.45833333 | C27: Balloon Darts 2 | E27: Court | F27: 0
B28: 0.47916667 | C28: Golden Snitch 2 | E28: Football Field | F28: 0
B29: 0.5 | C29: END OF BLOCK
E30: Total Deduction: | F30: =SUM(F4:F8,F12:F16,F20:F21,F25:F28) -> 0

Sheet F6.3
B1: F6.3 - GINEVRA / NADA N.
B2: Block 1 - Day 1
B3: Time | C3: Game | E3: Location | F3: Point Deduction
B4: 0.45833333 | C4: Chubby Bunny | E4: Pool | F4: 0
B5: 0.47222222 | C5: Scale | E5: Terrace | F5: 0
B6: 0.98611111 | C6: Cone Memory | E6: Court | F6: 0
B7: 0.5 | C7: Talk | D7: Big Mac | E7: Main Hall / Football Field | F7: 0
B8: 0.52083333 | C8: Big Mac | D8: Talk | E8: Football Field / Main Hall | F8: 0
B9: 0.54166667 | C9: END OF BLOCK
B10: Block 2 - Day 1
B11: Time | C11: Game | E11: Location | F11: Point Deduction
B12: 0.70833333 | C12: Cheesy Strings | E12: Football Field | F12: 0
B13: 0.72916667 | C13: Talk | E13: Main Hall | F13: 0
B14: 0.75 | C14: Lift | E14: Terrace | F14: 0
B15: 0.76388889 | C15: Puzzle | E15: Court | F15: 0
B16: 0.77777778 | C16: Bible Whispers | E16: Pool | F16: 0
B17: 0.79166667 | C17: END OF BLOCK
B18: Block 3 - Day 1
B19: Time | C19: Game | E19: Location | F19: Point Deduction
B20: 0.80208333 | C20: Talk 2 | E20: Main Hall | F20: 0 | H20: 1. Football Field
B21: 0.82291667 | C21: Big Bucket 2 | E21: Football Field | F21: 0 | H21: 2. Terrace
B22: 0.84375 | C22: END OF BLOCK | H22: 3. Court
B23: Block 4 - Day 2 | H23: 4. Pool
B24: Time | C24: Game | E24: Location | F24: Point Deduction | H24: 5. Roof
B25: 0.41666667 | C25: Talk 2 | E25: ? | F25: 0 | H25: MH = Main Hall
B26: 0.4375 | C26: Balloon Darts 2 | E26: Court | F26: 0
B27: 0.45833333 | C27: Golden Snitch 2 | E27: Football Field | F27: 0
B28: 0.47916667 | C28: Nadala+ 2 | E28: Roof | F28: 0
B29: 0.5 | C29: END OF BLOCK
E30: Total Deduction: | F30: =SUM(F4:F8,F12:F16,F20:F21,F25:F28) -> 0

Sheet S5.1
B1: S5.1 - KARINE K. / MARIA N.
B2: Block 1 - Day 1
B3: Time | C3: Game | E3: Location | F3: Point Deduction
B4: 0.45833333 | C4: Big Mac | E4: Football Field | F4: 0
B5: 0.47916667 | C5: Talk | E5: Main Hall | F5: 0
B6: 0.5 | C6: Cone Memory | E6: Court | F6: 0
B7: 0.51388889 | C7: Scale | E7: Terrace | F7: 0
B8: 0.52777778 | C8: Chubby Bunny | E8: Pool | F8: 0
B9: 0.54166667 | C9: END OF BLOCK
B10: Block 2 - Day 1
B11: Time | C11: Game | E11: Location | F11: Point Deduction
B12: 0.70833333 | C12: Puzzle | E12: Court | F12: 0
B13: 0.72222222 | C13: Lift | E13: Terrace | F13: 0
B14: 0.73611111 | C14: Bible Whispers | E14: Pool | F14: 0
B15: 0.75 | C15: Talk | D15: Cheesy Strings | E15: Main Hall / Football Field | F15: 0
B16: 0.77083333 | C16: Cheesy Strings | D16: Talk | E16: Football Field / Main Hall | F16: 0
B17: 0.79166667 | C17: END OF BLOCK
B18: Block 3 - Day 1
B19: Time | C19: Game | E19: Location | F19: Point Deduction
B20: 0.80208333 | C20: Big Bucket 1 | E20: Football Field 1 | F20: 0 | H20: 1. Football Field
B21: 0.82291667 | C21: Talk 1 | E21: Main Hall 1 | F21: 0 | H21: 2. Terrace
B22: 0.84375 | C22: END OF BLOCK | H22: 3. Court
B23: Block 4 - Day 2 | H23: 4. Pool
B24: Time | C24: Game | E24: Location | F24: Point Deduction | H24: 5. Roof
B25: 0.41666667 | C25: Golden Snitch 1 | E25: Football Field | F25: 0 | H25: MH = Main Hall
B26: 0.4375 | C26: Nadala+ 1 | E26: Roof | F26: 0
B27: 0.45833333 | C27: Talk 1 | E27: Main Hall 1 | F27: 0
B28: 0.47916667 | C28: Balloon Darts 1 | E28: Court | F28: 0
B29: 0.5 | C29: END OF BLOCK
E30: Total Deduction: | F30: =SUM(F4:F8,F12:F16,F20:F21,F25:F28) -> 0

Sheet S5.2
B1: S5.2 - MARLA I. / MARK E.
B2: Block 1 - Day 1
B3: Time | C3: Game | E3: Location | F3: Point Deduction
B4: 0.45833333 | C4: Talk | E4: Main Hall | F4: 0
B5: 0.47916667 | C5: Big Mac | E5: Football Field | F5: 0
B6: 0.5 | C6: Scale | E6: Terrace | F6: 0
B7: 0.51388889 | C7: Chubby Bunny | E7: Pool | F7: 0
B8: 0.52777778 | C8: Cone Memory | E8: Court | F8: 0
B9: 0.54166667 | C9: END OF BLOCK
B10: Block 2 - Day 1
B11: Time | C11: Game | E11: Location | F11: Point Deduction
B12: 0.70833333 | C12: Bible Whispers | E12: Pool | F12: 0
B13: 0.72222222 | C13: Puzzle | E13: Court | F13: 0
B14: 0.73611111 | C14: Lift | E14: Terrace | F14: 0
B15: 0.75 | C15: Talk | E15: Main Hall | F15: 0
B16: 0.77083333 | C16: Cheesy Strings | E16: Football Field | F16: 0
B17: 0.79166667 | C17: END OF BLOCK
B18: Block 3 - Day 1
B19: Time | C19: Game | E19: Location | F19: Point Deduction
B20: 0.80208333 | C20: Talk 1 | D20: Big Bucket 1 | E20: Main Hall / Football Field | F20: 0 | H20: 1. Football Field
B21: 0.82291667 | C21: Big Bucket 1 | D21: Talk 1 | E21: Football Field / Main Hall | F21: 0 | H21: 2. Terrace
B22: 0.84375 | C22: END OF BLOCK | H22: 3. Court
B23: Block 4 - Day 2 | H23: 4. Pool
B24: Time | C24: Game | E24: Location | F24: Point Deduction | H24: 5. Roof
B25: 0.41666667 | C25: Nadala+ 1 | E25: Roof | F25: 0 | H25: MH = Main Hall
B26: 0.4375 | C26: Talk 1 | E26: Main Hall 1 | F26: 0
B27: 0.45833333 | C27: Balloon Darts 1 | E27: Court | F27: 0
B28: 0.47916667 | C28: Golden Snitch 1 | E28: Football Field | F28: 0
B29: 0.5 | C29: END OF BLOCK
E30: Total Deduction: | F30: =SUM(F4:F8,F12:F16,F20:F21,F25:F28) -> 0

Sheet S5.3
B1: S5.3 - YOUSSEF S. /MARINA A.
B2: Block 1 - Day 1
B3: Time | C3: Game | E3: Location | F3: Point Deduction
B4: 0.45833333 | C4: Talk | D4: Big Mac | E4: Main Hall / Football Field | F4: 0
B5: 0.47916667 | C5: Big Mac | D5: Talk | E5: Football Field / Main Hall | F5: 0
B6: 0.5 | C6: Chubby Bunny | E6: Pool | F6: 0
B7: 0.51388889 | C7: Cone Memory | E7: Court | F7: 0
B8: 0.52777778 | C8: Scale | E8: Terrace | F8: 0
B9: 0.54166667 | C9: END OF BLOCK
B10: Block 2 - Day 1
B11: Time | C11: Game | E11: Location | F11: Point Deduction
B12: 0.70833333 | C12: Lift | E12: Terrace | F12: 0
B13: 0.72222222 | C13: Bible Whispers | E13: Pool | F13: 0
B14: 0.73611111 | C14: Puzzle | E14: Court | F14: 0
B15: 0.75 | C15: Cheesy Strings | E15: Football Field | F15: 0
B16: 0.77083333 | C16: Talk | E16: Main Hall | F16: 0
B17: 0.79166667 | C17: END OF BLOCK
B18: Block 3 - Day 1
B19: Time | C19: Game | E19: Location | F19: Point Deduction
B20: 0.80208333 | C20: Talk 1 | E20: Main Hall 1 | F20: 0 | H20: 1. Football Field
B21: 0.82291667 | C21: Big Bucket 1 | E21: Football Field 1 | F21: 0 | H21: 2. Terrace
B22: 0.84375 | C22: END OF BLOCK | H22: 3. Court
B23: Block 4 - Day 2 | H23: 4. Pool
B24: Time | C24: Game | E24: Location | F24: Point Deduction | H24: 5. Roof
B25: 0.41666667 | C25: Talk 1 | E25: Main Hall 1 | F25: 0 | H25: MH = Main Hall
B26: 0.4375 | C26: Balloon Darts 1 | E26: Court | F26: 0
B27: 0.45833333 | C27: Golden Snitch 1 | E27: Football Field | F27: 0
B28: 0.47916667 | C28: Nadala+ 1 | E28: Roof | F28: 0
B29: 0.5 | C29: END OF BLOCK
E30: Total Deduction: | F30: =SUM(F4:F8,F12:F16,F20:F21,F25:F28) -> 0

Sheet S6.1
B1: S6.1 - JASON / DANIEL S.
B2: Block 1 - Day 1
B3: Time | C3: Game | E3: Location | F3: Point Deduction
B4: 0.45833333 | C4: Chubby Bunny | E4: Pool | F4: 0
B5: 0.47222222 | C5: Cone Memory | E5: Court | F5: 0
B6: 0.98611111 | C6: Scale | E6: Terrace | F6: 0
B7: 0.5 | C7: Talk | D7: Big Mac | E7: Main Hall / Football Field | F7: 0
B8: 0.52083333 | C8: Big Mac | D8: Talk | E8: Football Field / Main Hall | F8: 0
B9: 0.54166667 | C9: END OF BLOCK
B10: Block 2 - Day 1
B11: Time | C11: Game | E11: Location | F11: Point Deduction
B12: 0.70833333 | C12: Talk | E12: Main Hall | F12: 0
B13: 0.72916667 | C13: Cheesy Strings | E13: Football Field | F13: 0
B14: 0.75 | C14: Bible Whispers | E14: Pool | F14: 0
B15: 0.76388889 | C15: Puzzle | E15: Court | F15: 0
B16: 0.77777778 | C16: Lift | E16: Terrace | F16: 0
B17: 0.79166667 | C17: END OF BLOCK
B18: Block 3 - Day 1
B19: Time | C19: Game | E19: Location | F19: Point Deduction
B20: 0.80208333 | C20: Big Bucket 2 | E20: Football Field | F20: 0 | H20: 1. Football Field
B21: 0.82291667 | C21: Talk 2 | E21: Main Hall | F21: 0 | H21: 2. Terrace
B22: 0.84375 | C22: END OF BLOCK | H22: 3. Court
B23: Block 4 - Day 2 | H23: 4. Pool
B24: Time | C24: Game | E24: Location | F24: Point Deduction | H24: 5. Roof
B25: 0.41666667 | C25: Golden Snitch 2 | E25: Football Field | F25: 0 | H25: MH = Main Hall
B26: 0.4375 | C26: Nadala+ 2 | E26: Roof | F26: 0
B27: 0.45833333 | C27: Talk 2 | E27: Main Hall | F27: 0
B28: 0.47916667 | C28: Balloon Darts 2 | E28: Court | F28: 0
B29: 0.5 | C29: END OF BLOCK
E30: Total Deduction: | F30: =SUM(F4:F8,F12:F16,F20:F21,F25:F28) -> 0

Sheet S6.2
B1: S6.2 - PHILO E. / MARK
B2: Block 1 - Day 1
B3: Time | C3: Game | E3: Location | F3: Point Deduction
B4: 0.45833333 | C4: Scale | E4: Terrace | F4: 0
B5: 0.47222222 | C5: Chubby Bunny | E5: Pool | F5: 0
B6: 0.98611111 | C6: Cone Memory | E6: Court | F6: 0
B7: 0.5 | C7: Talk | E7: Main Hall | F7: 0
B8: 0.52083333 | C8: Big Mac | E8: Football Field | F8: 0
B9: 0.54166667 | C9: END OF BLOCK
B10: Block 2 - Day 1
B11: Time | C11: Game | E11: Location | F11: Point Deduction
B12: 0.70833333 | C12: Talk | D12: Cheesy Strings | E12: Main Hall / Football Field | F12: 0
B13: 0.72916667 | C13: Cheesy Strings | D13: Talk | E13: Football Field / Main Hall | F13: 0
B14: 0.75 | C14: Puzzle | E14: Court | F14: 0
B15: 0.76388889 | C15: Lift | E15: Terrace | F15: 0
B16: 0.77777778 | C16: Bible Whispers | E16: Pool | F16: 0
B17: 0.79166667 | C17: END OF BLOCK
B18: Block 3 - Day 1
B19: Time | C19: Game | E19: Location | F19: Point Deduction
B20: 0.80208333 | C20: Talk 2 | E20: Main Hall | F20: 0 | H20: 1. Football Field
B21: 0.82291667 | C21: Big Bucket 2 | E21: Football Field | F21: 0 | H21: 2. Terrace
B22: 0.84375 | C22: END OF BLOCK | H22: 3. Court
B23: Block 4 - Day 2 | H23: 4. Pool
B24: Time | C24: Game | E24: Location | F24: Point Deduction | H24: 5. Roof
B25: 0.41666667 | C25: Nadala+ 2 | E25: Roof | F25: 0 | H25: MH = Main Hall
B26: 0.4375 | C26: Talk 2 | E26: Main Hall | F26: 0
B27: 0.45833333 | C27: Balloon Darts 2 | E27: Court | F27: 0
B28: 0.47916667 | C28: Golden Snitch 2 | E28: Football Field | F28: 0
B29: 0.5 | C29: END OF BLOCK
E30: Total Deduction: | F30: =SUM(F4:F8,F12:F16,F20:F21,F25:F28) -> 0

Sheet S6.3
B1: S6.3 - MARIA E. / JOHN E.
B2: Block 1 - Day 1
B3: Time | C3: Game | E3: Location | F3: Point Deduction
B4: 0.45833333 | C4: Cone Memory | E4: Court | F4: 0
B5: 0.47222222 | C5: Scale | E5: Terrace | F5: 0
B6: 0.98611111 | C6: Chubby Bunny | E6: Pool | F6: 0
B7: 0.5 | C7: Big Mac | E7: Football Field | F7: 0
B8: 0.52083333 | C8: Talk | E8: Main Hall | F8: 0
B9: 0.54166667 | C9: END OF BLOCK
B10: Block 2 - Day 1
B11: Time | C11: Game | E11: Location | F11: Point Deduction
B12: 0.70833333 | C12: Cheesy Strings | E12: Football Field | F12: 0
B13: 0.72916667 | C13: Talk | E13: Main Hall | F13: 0
B14: 0.75 | C14: Lift | E14: Terrace | F14: 0
B15: 0.76388889 | C15: Bible Whispers | E15: Pool | F15: 0
B16: 0.77777778 | C16: Puzzle | E16: Court | F16: 0
B17: 0.79166667 | C17: END OF BLOCK
B18: Block 3 - Day 1
B19: Time | C19: Game | E19: Location | F19: Point Deduction
B20: 0.80208333 | C20: Talk 2 | D20: Big Bucket 2 | E20: Main Hall / Football Field | F20: 0 | H20: 1. Football Field
B21: 0.82291667 | C21: Big Bucket 2 | D21: Talk 2 | E21: Football Field / Main Hall | F21: 0 | H21: 2. Terrace
B22: 0.84375 | C22: END OF BLOCK | H22: 3. Court
B23: Block 4 - Day 2 | H23: 4. Pool
B24: Time | C24: Game | E24: Location | F24: Point Deduction | H24: 5. Roof
B25: 0.41666667 | C25: Talk 2 | E25: Main Hall | F25: 0 | H25: MH = Main Hall
B26: 0.4375 | C26: Balloon Darts 2 | E26: Court | F26: 0
B27: 0.45833333 | C27: Golden Snitch 2 | E27: Football Field | F27: 0
B28: 0.47916667 | C28: Nadala+ 2 | E28: Roof | F28: 0
B29: 0.5 | C29: END OF BLOCK
E30: Total Deduction: | F30: =SUM(F4:F8,F12:F16,F20:F21,F25:F28) -> 0

Sheet Game Schedule
B2: Block 1
A4: TIme | B4: Big Mac | D4: Talk | F4: SPLIT | H4: TIme | I4: Cone Memory | K4: Scale | M4: Chubby Bunny
A5: 0.45833333 | B5: Karine | C5: Karen | D5: Marla | E5: Shady | F5: Youssef | G5: Kirmina | H5: 0.45833333 | I5: Maria | J5: Sherry | K5: Philo | L5: Roberto | M5: Jason | N5: Gin
A6: 0.47916667 | B6: Marla | C6: Shady | D6: Karine | E6: Karen | F6: Youssef | G6: Kirmina | H6: 0.47222222 | I6: Jason | J6: Roberto | K6: Maria | L6: Gin | M6: Philo | N6: Sherry
H7: 0.98611111 | I7: Philo | J7: Gin | K7: Jason | L7: Sherry | M7: Maria | N7: Roberto
A8: 0.5 | B8: Maria | C8: Sherry | D8: Philo | E8: Roberto | F8: Jason | G8: Gin | H8: 0.5 | I8: Karine | J8: Karen | K8: Marla | L8: Shady | M8: Youssef | N8: Kirmina
A9: 0.52083333 | B9: Philo | C9: Roberto | D9: Maria | E9: Sherry | F9: Jason | G9: Gin | H9: 0.51388889 | I9: Youssef | J9: Shady | K9: Karine | L9: Kirmina | M9: Marla | N9: Karen
H10: 0.52777778 | I10: Marla | J10: Kirmina | K10: Youssef | L10: Karen | M10: Karine | N10: Shady
B12: Block 2
B14: Cheesy Strings | D14: Talk | F14: SPLIT | I14: Lift | K14: Bible Whisper | M14: Puzzle
A15: 0.70833333 | B15: Maria | C15: Gin | D15: Jason | E15: Sherry | F15: Philo | G15: Roberto | H15: 0.70833333 | I15: Youssef | J15: Kirmina | K15: Marla | L15: Karen | M15: Karine | N15: Shady
A16: 0.72916667 | B16: Jason | C16: Sherry | D16: Maria | E16: Gin | F16: Philo | G16: Roberto | H16: 0.72222222 | I16: Karine | J16: Karen | K16: Youssef | L16: Shady | M16: Marla | N16: Kirmina
H17: 0.73611111 | I17: Marla | J17: Shady | K17: Karine | L17: Kirmina | M17: Youssef | N17: Karen
A18: 0.75 | B18: Youssef | C18: Kirmina | D18: Marla | E18: Karen | F18: Karine | G18: Shady | H18: 0.75 | I18: Maria | J18: Gin | K18: Jason | L18: Sherry | M18: Philo | N18: Roberto
A19: 0.77083333 | B19: Marla | C19: Karen | D19: Youssef | E19: Kirmina | F19: Karine | G19: Shady | H19: 0.76388889 | I19: Philo | J19: Sherry | K19: Maria | L19: Roberto | M19: Jason | N19: Gin
H20: 0.77777778 | I20: Jason | J20: Roberto | K20: Philo | L20: Gin | M20: Maria | N20: Sherry
B22: Block 3
B24: Talk 1 | D24: Big Bucket 1 | F24: Split 1 | I24: Talk 2 | K24: Big Bucket 2 | M24: Split 2
A25: 0.80208333 | B25: Youssef | C25: Shady | D25: Karine | E25: Kirmina | F25: Marla | G25: Karen | H25: 0.80208333 | I25: Philo | J25: Gin | K25: Jason | L25: Roberto | M25: Maria | N25: Sherry
A26: 0.82291667 | B26: Karine | C26: Kirmina | D26: Youssef | E26: Shady | F26: Marla | G26: Karen | H26: 0.82291667 | I26: Jason | J26: Roberto | K26: Philo | L26: Gin | M26: Maria | N26: Sherry
B28: Block 4
E30: Balloon Darts 1 | G30: Golden Snitch 1 | I30: Nadala+ 1 | K30: Talk 1
D31: 0.41666667 | E31: NA | G31: Karine | H31: Karen | I31: Marla | J31: Shady | K31: Youssef | L31: Kirmina
D32: 0.4375 | E32: Youssef | F32: Kirmina | G32: NA | I32: Karine | J32: Karen | K32: Marla | L32: Shady
D33: 0.45833333 | E33: Marla | F33: Shady | G33: Youssef | H33: Kirmina | I33: NA | K33: Karine | L33: Karen
D34: 0.47916667 | E34: Karine | F34: Karen | G34: Marla | H34: Shady | I34: Youssef | J34: Kirmina | K34: NA
E36: Balloon Darts 2 | G36: Golden Snitch 2 | I36: Nadala+ 2 | K36: Talk 2
D37: 0.41666667 | E37: NA | G37: Jason | H37: Sherry | I37: Philo | J37: Roberto | K37: Maria | L37: Gin
D38: 0.4375 | E38: Maria | F38: Gin | G38: NA | I38: Jason | J38: Sherry | K38: Philo | L38: Roberto
D39: 0.45833333 | E39: Philo | F39: Roberto | G39: Maria | H39: Gin | I39: NA | K39: Jason | L39: Sherry
D40: 0.47916667 | E40: Jason | F40: Sherry | G40: Philo | H40: Roberto | I40: Maria | J40: Gin | K40: NA

Sheet Overall Schedule

Sheet Fries Schedules
B2: F5.1 - KAREN T. / MADONNA H. | G2: F5.2 - SHADY S. / MARY F. | L2: F5.3 - KIRMINA S. / JOHN A.
B3: Block 1 - Day 1 | G3: Block 1 - Day 1 | L3: Block 1 - Day 1
B4: Time | C4: Game | E4: Location | G4: Time | H4: Game | J4: Location | L4: Time | M4: Game | O4: Location
B5: 0.45833333 | C5: Big Mac | E5: Football Field | G5: 0.45833333 | H5: Talk | J5: Main Hall | L5: 0.45833333 | M5: Talk | N5: Big Mac | O5: Main Hall / Football Field
B6: 0.47916667 | C6: Talk | E6: Main Hall | G6: 0.47916667 | H6: Big Mac | J6: Football Field | L6: 0.47916667 | M6: Big Mac | N6: Talk | O6: Football Field / Main Hall
B7: 0.5 | C7: Cone Memory | E7: Court | G7: 0.5 | H7: Scale | J7: Terrace | L7: 0.5 | M7: Chubby Bunny | O7: Pool
B8: 0.51388889 | C8: Chubby Bunny | E8: Pool | G8: 0.51388889 | H8: Cone Memory | J8: Court | L8: 0.51388889 | M8: Scale | O8: Terrace
B9: 0.52777778 | C9: Scale | E9: Terrace | G9: 0.52777778 | H9: Chubby Bunny | J9: Pool | L9: 0.52777778 | M9: Cone Memory | O9: Court
B10: 0.54166667 | C10: END OF BLOCK | G10: 0.54166667 | H10: END OF BLOCK | L10: 0.54166667 | M10: END OF BLOCK
B11: Block 2 - Day 1 | G11: Block 2 - Day 1 | L11: Block 2 - Day 1
B12: Time | C12: Game | E12: Location | G12: Time | H12: Game | J12: Location | L12: Time | M12: Game | O12: Location
B13: 0.70833333 | C13: Bible Whispers | E13: Pool | G13: 0.70833333 | H13: Puzzle | J13: Court | L13: 0.70833333 | M13: Lift | O13: Terrace
B14: 0.72222222 | C14: Lift | E14: Terrace | G14: 0.72222222 | H14: Bible Whispers | J14: Pool | L14: 0.72222222 | M14: Puzzle | O14: Court
B15: 0.73611111 | C15: Puzzle | E15: Court | G15: 0.73611111 | H15: Lift | J15: Terrace | L15: 0.73611111 | M15: Bible Whispers | O15: Pool
B16: 0.75 | C16: Talk | E16: Main Hall | G16: 0.75 | H16: Talk | I16: Cheesy Strings | J16: Main Hall / Football Field | L16: 0.75 | M16: Cheesy Strings | O16: Football Field
B17: 0.77083333 | C17: Cheesy Strings | E17: Football Field | G17: 0.77083333 | H17: Cheesy Strings | I17: Talk | J17: Football Field / Main Hall | L17: 0.77083333 | M17: Talk | O17: Main Hall
B18: 0.79166667 | C18: END OF BLOCK | G18: 0.79166667 | H18: END OF BLOCK | L18: 0.79166667 | M18: END OF BLOCK
B19: Block 3 - Day 1 | G19: Block 3 - Day 1 | L19: Block 3 - Day 1
B20: Time | C20: Game | E20: Location | G20: Time | H20: Game | J20: Location | L20: Time | M20: Game | O20: Location
B21: 0.80208333 | C21: Talk 1 | D21: Big Bucket 1 | E21: Main Hall / Football Field | G21: 0.80208333 | H21: Talk 1 | J21: Main Hall 1 | L21: 0.80208333 | M21: Talk 1 | O21: Main Hall 1
B22: 0.82291667 | C22: Big Bucket 1 | D22: Talk 1 | E22: Football Field / Main Hall | G22: 0.82291667 | H22: Big Bucket 1 | J22: Football Field 1 | L22: 0.82291667 | M22: Big Bucket 1 | O22: Football Field 1
B23: 0.84375 | C23: END OF BLOCK | G23: 0.84375 | H23: END OF BLOCK | L23: 0.84375 | M23: END OF BLOCK
B24: Block 4 - Day 2 | G24: Block 4 - Day 2 | L24: Block 4 - Day 2
B25: Time | C25: Game | E25: Location | G25: Time | H25: Game | J25: Location | L25: Time | M25: Game | O25: Location
B26: 0.41666667 | C26: Golden Snitch 1 | E26: Football Field | G26: 0.41666667 | H26: Nadala+ 1 | J26: Roof | L26: 0.41666667 | M26: Talk 1 | O26: Main Hall 1
B27: 0.4375 | C27: Nadala+ 1 | E27: Roof | G27: 0.4375 | H27: Talk 1 | J27: Main Hall 1 | L27: 0.4375 | M27: Balloon Darts 1 | O27: Court
B28: 0.45833333 | C28: Talk 1 | E28: Main Hall 1 | G28: 0.45833333 | H28: Balloon Darts 1 | J28: Court | L28: 0.45833333 | M28: Golden Snitch 1 | O28: Football Field
B29: 0.47916667 | C29: Balloon Darts 1 | E29: Court | G29: 0.47916667 | H29: Golden Snitch 1 | J29: Football Field | L29: 0.47916667 | M29: Nadala+ 1 | O29: Roof
B30: 0.5 | C30: END OF BLOCK | G30: 0.5 | H30: END OF BLOCK | L30: 0.5 | M30: END OF BLOCK
B32: F6.1 - SHERRY W. / KIRO | G32: F6.2 - ROBERTO / MICHAEL H. | L32: F6.3 - GINEVRA / NADA N.
B33: Block 1 - Day 1 | G33: Block 1 - Day 1 | L33: Block 1 - Day 1
B34: Time | C34: Game | E34: Location | G34: Time | H34: Game | J34: Location | L34: Time | M34: Game | O34: Location
B35: 0.45833333 | C35: Cone Memory | E35: Court | G35: 0.45833333 | H35: Scale | J35: Terrace | L35: 0.45833333 | M35: Chubby Bunny | O35: Pool
B36: 0.47222222 | C36: Chubby Bunny | E36: Pool | G36: 0.47222222 | H36: Cone Memory | J36: Court | L36: 0.47222222 | M36: Scale | O36: Terrace
B37: 0.98611111 | C37: Scale | E37: Terrace | G37: 0.98611111 | H37: Chubby Bunny | J37: Pool | L37: 0.98611111 | M37: Cone Memory | O37: Court
B38: 0.5 | C38: Big Mac | E38: Football Field | G38: 0.5 | H38: Talk | J38: Main Hall | L38: 0.5 | M38: Talk | N38: Big Mac | O38: Main Hall / Football Field
B39: 0.52083333 | C39: Talk | E39: Main Hall | G39: 0.52083333 | H39: Big Mac | J39: Football Field | L39: 0.52083333 | M39: Big Mac | N39: Talk | O39: Football Field / Main Hall
B40: 0.54166667 | C40: END OF BLOCK | G40: 0.54166667 | H40: END OF BLOCK | L40: 0.54166667 | M40: END OF BLOCK
B41: Block 2 - Day 1 | G41: Block 2 - Day 1 | L41: Block 2 - Day 1
B42: Time | C42: Game | E42: Location | G42: Time | H42: Game | J42: Location | L42: Time | M42: Game | O42: Location
...

Sheet Shakes Schedules
B2: S5.1 - KARINE K. / MARIA N. | G2: S5.2 - MARLA I. / MARK E. | L2: S5.3 - YOUSSEF S. /MARINA A.
B3: Block 1 - Day 1 | G3: Block 1 - Day 1 | L3: Block 1 - Day 1
B4: Time | C4: Game | E4: Location | G4: Time | H4: Game | J4: Location | L4: Time | M4: Game | O4: Location
B5: 0.45833333 | C5: Big Mac | E5: Football Field | G5: 0.45833333 | H5: Talk | J5: Main Hall | L5: 0.45833333 | M5: Talk | N5: Big Mac | O5: Main Hall / Football Field
B6: 0.47916667 | C6: Talk | E6: Main Hall | G6: 0.47916667 | H6: Big Mac | J6: Football Field | L6: 0.47916667 | M6: Big Mac | N6: Talk | O6: Football Field / Main Hall
B7: 0.5 | C7: Cone Memory | E7: Court | G7: 0.5 | H7: Scale | J7: Terrace | L7: 0.5 | M7: Chubby Bunny | O7: Pool
B8: 0.51388889 | C8: Scale | E8: Terrace | G8: 0.51388889 | H8: Chubby Bunny | J8: Pool | L8: 0.51388889 | M8: Cone Memory | O8: Court
B9: 0.52777778 | C9: Chubby Bunny | E9: Pool | G9: 0.52777778 | H9: Cone Memory | J9: Court | L9: 0.52777778 | M9: Scale | O9: Terrace
B10: 0.54166667 | C10: END OF BLOCK | G10: 0.54166667 | H10: END OF BLOCK | L10: 0.54166667 | M10: END OF BLOCK
B11: Block 2 - Day 1 | G11: Block 2 - Day 1 | L11: Block 2 - Day 1
B12: Time | C12: Game | E12: Location | G12: Time | H12: Game | J12: Location | L12: Time | M12: Game | O12: Location
B13: 0.70833333 | C13: Puzzle | E13: Court | G13: 0.70833333 | H13: Bible Whispers | J13: Pool | L13: 0.70833333 | M13: Lift | O13: Terrace
B14: 0.72222222 | C14: Lift | E14: Terrace | G14: 0.72222222 | H14: Puzzle | J14: Court | L14: 0.72222222 | M14: Bible Whispers | O14: Pool
B15: 0.73611111 | C15: Bible Whispers | E15: Pool | G15: 0.73611111 | H15: Lift | J15: Terrace | L15: 0.73611111 | M15: Puzzle | O15: Court
B16: 0.75 | C16: Talk | D16: Cheesy Strings | E16: Main Hall / Football Field | G16: 0.75 | H16: Talk | J16: Main Hall | L16: 0.75 | M16: Cheesy Strings | O16: Football Field
B17: 0.77083333 | C17: Cheesy Strings | D17: Talk | E17: Football Field / Main Hall | G17: 0.77083333 | H17: Cheesy Strings | J17: Football Field | L17: 0.77083333 | M17: Talk | O17: Main Hall
B18: 0.79166667 | C18: END OF BLOCK | G18: 0.79166667 | H18: END OF BLOCK | L18: 0.79166667 | M18: END OF BLOCK
B19: Block 3 - Day 1 | G19: Block 3 - Day 1 | L19: Block 3 - Day 1
B20: Time | C20: Game | E20: Location | G20: Time | H20: Game | J20: Location | L20: Time | M20: Game | O20: Location
B21: 0.80208333 | C21: Big Bucket 1 | E21: Football Field 1 | G21: 0.80208333 | H21: Talk 1 | I21: Big Bucket 1 | J21: Main Hall / Football Field | L21: 0.80208333 | M21: Talk 1 | O21: Main Hall 1
B22: 0.82291667 | C22: Talk 1 | E22: Main Hall 1 | G22: 0.82291667 | H22: Big Bucket 1 | I22: Talk 1 | J22: Football Field / Main Hall | L22: 0.82291667 | M22: Big Bucket 1 | O22: Football Field 1
B23: 0.84375 | C23: END OF BLOCK | G23: 0.84375 | H23: END OF BLOCK | L23: 0.84375 | M23: END OF BLOCK
B24: Block 4 - Day 2 | G24: Block 4 - Day 2 | L24: Block 4 - Day 2
B25: Time | C25: Game | E25: Location | G25: Time | H25: Game | J25: Location | L25: Time | M25: Game | O25: Location
B26: 0.41666667 | C26: Golden Snitch 1 | E26: Football Field | G26: 0.41666667 | H26: Nadala+ 1 | J26: Roof | L26: 0.41666667 | M26: Talk 1 | O26: Main Hall 1
B27: 0.4375 | C27: Nadala+ 1 | E27: Roof | G27: 0.4375 | H27: Talk 1 | J27: Main Hall 1 | L27: 0.4375 | M27: Balloon Darts 1 | O27: Court
B28: 0.45833333 | C28: Talk 1 | E28: Main Hall 1 | G28: 0.45833333 | H28: Balloon Darts 1 | J28: Court | L28: 0.45833333 | M28: Golden Snitch 1 | O28: Football Field
B29: 0.47916667 | C29: Balloon Darts 1 | E29: Court | G29: 0.47916667 | H29: Golden Snitch 1 | J29: Football Field | L29: 0.47916667 | M29: Nadala+ 1 | O29: Roof
B30: 0.5 | C30: END OF BLOCK | G30: 0.5 | H30: END OF BLOCK | L30: 0.5 | M30: END OF BLOCK
B32: S6.1 - JASON / DANIEL S. | G32: S6.2 - PHILO E. / MARK | L32: S6.3 - MARIA E. / JOHN E.
B33: Block 1 - Day 1 | G33: Block 1 - Day 1 | L33: Block 1 - Day 1
B34: Time | C34: Game | E34: Location | G34: Time | H34: Game | J34: Location | L34: Time | M34: Game | O34: Location
B35: 0.45833333 | C35: Chubby Bunny | E35: Pool | G35: 0.45833333 | H35: Scale | J35: Terrace | L35: 0.45833333 | M35: Cone Memory | O35: Court
B36: 0.47222222 | C36: Cone Memory | E36: Court | G36: 0.47222222 | H36: Chubby Bunny | J36: Pool | L36: 0.47222222 | M36: Scale | O36: Terrace
B37: 0.98611111 | C37: Scale | E37: Terrace | G37: 0.98611111 | H37: Cone Memory | J37: Court | L37: 0.98611111 | M37: Chubby Bunny | O37: Pool
B38: 0.5 | C38: Talk | D38: Big Mac | E38: Main Hall / Football Field | G38: 0.5 | H38: Talk | J38: Main Hall | L38: 0.5 | M38: Big Mac | O38: Football Field
B39: 0.52083333 | C39: Big Mac | D39: Talk | E39: Football Field / Main Hall | G39: 0.52083333 | H39: Big Mac | J39: Football Field | L39: 0.52083333 | M39: Talk | O39: Main Hall
B40: 0.54166667 | C40: END OF BLOCK | G40: 0.54166667 | H40: END OF BLOCK | L40: 0.54166667 | M40: END OF BLOCK
B41: Block 2 - Day 1 | G41: Block 2 - Day 1 | L41: Block 2 - Day 1
B42: Time | C42: Game | E42: Location | G42: Time | H42: Game | J42: Location | L42: Time | M42: Game | O42: Location
...

Sheet Talk Schedule
B2: Block 1
C3: Servant | D3: Location | E3: Talk | G3: SPLIT
B4: 0.45833333 | D4: Main Hall | E4: Marla | F4: Shady | G4: Youssef | H4: Kirmina
B5: 0.47916667 | D5: Main Hall | E5: Karine | F5: Karen | G5: Youssef | H5: Kirmina
B6: 0.5 | D6: Main Hall | E6: Philo | F6: Roberto | G6: Jason | H6: Gin
B7: 0.52083333 | D7: Main Hall | E7: Maria | F7: Sherry | G7: Jason | H7: Gin
B9: Block 2
C10: Servant | D10: Location | E10: Talk | G10: SPLIT
B11: 0.70833333 | D11: Main Hall | E11: Jason | F11: Sherry | G11: Philo | H11: Roberto
B12: 0.72916667 | D12: Main Hall | E12: Maria | F12: Gin | G12: Philo | H12: Roberto
B13: 0.75 | D13: Main Hall | E13: Marla | F13: Karen | G13: Karine | H13: Shady
B14: 0.77083333 | D14: Main Hall | E14: Youssef | F14: Kirmina | G14: Karine | H14: Shady
B16: Block 3
C17: Servant | D17: Location | E17: Talk 1 | G17: Split 1
B18: 0.80208333 | D18: Main Hall | E18: Youssef | F18: Shady | G18: Marla | H18: Karen
B19: 0.82291667 | D19: ? | E19: Karine | F19: Kirmina | G19: Marla | H19: Karen
C21: Servant | D21: Location | E21: Talk 2 | G21: Split 2
B22: 0.80208333 | D22: Main Hall | E22: Philo | F22: Gin | G22: Maria | H22: Sherry
B23: 0.82291667 | D23: ? | E23: Jason | F23: Roberto | G23: Maria | H23: Sherry
B25: Block 4
C26: Servant | D26: Location | E26: Talk 1
B27: 0.47916667 | D27: Main Hall | E27: Youssef | F27: Marla | G27: Shady | H27: Karen
E29: Talk 2
B30: 0.47916667 | D30: ? | E30: Philo | F30: Maria | G30: Gin | H30: Sherry

Sheet Game Locations
B2: Block 1 | F2: Block 2
C4: Game | D4: Location | G4: Game | H4: Location
C5: Big Mac | D5: Football Field | G5: Bible Whispers | H5: Pool
C6: Talk | D6: Main Hall | G6: Lift | H6: Terrace
C7: Cone Memory | D7: Court | G7: Puzzle | H7: Court
C8: Chubby Bunny | D8: Pool | G8: Talk | H8: Main Hall
C9: Scale | D9: Terrace | G9: Cheesy Strings | H9: Football Field
B11: Block 3 | F11: Block 4
C13: Talk | D13: Main Hall | G13: Balloon Darts 1 | H13: Court
C14: Big Bucket | D14: Football Field | G14: Nadala+ 1 | H14: Roof
G15: Golden Snitch 1 | H15: Football Field
G16: Balloon Darts 2 | H16: Pool
G17: Nadala+ 2 | H17: Roof
G18: Golden Snitch 2 | H18: Football Field
C22: 1. Football Field
C23: 2. Terrace
C24: 3. Court
C25: 4. Pool
C26: 5. Roof
C27: MH = Main Hall

Sheet Points Bar Chart

Sheet Score Calculator
C2: Block 1 - Temporary fill
H3: Shakes | I3: Fries
C4: Big Mac | D4: Cone Memory | E4: Scale | F4: Chubby Bunny
B5: Round 1 | C5: NA | D5: NA | E5: NA | F5: NA | H5: =IF(C5="Shakes",30,0)+IF(D5="Shakes",15,0)+IF(E5="Shakes",15,0)+IF(F5="Shakes",15,0) -> 0 | I5: =IF(C5="Fries",30,0)+IF(D5="Fries",15,0)+IF(E5="Fries",15,0)+IF(F5="Fries",15,0) -> 0
B6: Round 2 | C6: NA | D6: NA | E6: NA | F6: NA | H6: =IF(C6="Shakes",30,0)+IF(D6="Shakes",15,0)+IF(E6="Shakes",15,0)+IF(F6="Shakes",15,0) -> 0 | I6: =IF(C6="Fries",30,0)+IF(D6="Fries",15,0)+IF(E6="Fries",15,0)+IF(F6="Fries",15,0) -> 0
B7: Round 3 | C7: NA | D7: NA | E7: NA | F7: NA | H7: =IF(C7="Shakes",30,0)+IF(D7="Shakes",15,0)+IF(E7="Shakes",15,0)+IF(F7="Shakes",15,0) -> 0 | I7: =IF(C7="Fries",30,0)+IF(D7="Fries",15,0)+IF(E7="Fries",15,0)+IF(F7="Fries",15,0) -> 0
B8: Round 4 | C8: NA | D8: NA | E8: NA | F8: NA | H8: =IF(C8="Shakes",30,0)+IF(D8="Shakes",15,0)+IF(E8="Shakes",15,0)+IF(F8="Shakes",15,0) -> 0 | I8: =IF(C8="Fries",30,0)+IF(D8="Fries",15,0)+IF(E8="Fries",15,0)+IF(F8="Fries",15,0) -> 0
B9: Round 5 | D9: NA | E9: NA | F9: NA | H9: =IF(C9="Shakes",30,0)+IF(D9="Shakes",15,0)+IF(E9="Shakes",15,0)+IF(F9="Shakes",15,0) -> 0 | I9: =IF(C9="Fries",30,0)+IF(D9="Fries",15,0)+IF(E9="Fries",15,0)+IF(F9="Fries",15,0) -> 0
B10: Round 6 | D10: NA | E10: NA | F10: NA | H10: =IF(C10="Shakes",30,0)+IF(D10="Shakes",15,0)+IF(E10="Shakes",15,0)+IF(F10="Shakes",15,0) -> 0 | I10: =IF(C10="Fries",30,0)+IF(D10="Fries",15,0)+IF(E10="Fries",15,0)+IF(F10="Fries",15,0) -> 0
G11: Block 1 Total: | H11: =SUM(H5:H10) -> 0 | I11: =SUM(I5:I10) -> 0
C13: Block 2 - Busy vs Blessed
H14: Shakes | I14: Fries
C15: Cheesy Strings | D15: Lift | E15: Bible Whispers | F15: Puzzle
B16: Round 1 | C16: NA | D16: NA | E16: NA | F16: NA | H16: =IF(C16="Shakes",30,0)+IF(D16="Shakes",15,0)+IF(E16="Shakes",15,0)+IF(F16="Shakes",15,0) -> 0 | I16: =IF(C16="Fries",30,0)+IF(D16="Fries",15,0)+IF(E16="Fries",15,0)+IF(F16="Fries",15,0) -> 0
B17: Round 2 | C17: NA | D17: NA | E17: NA | F17: NA | H17: =IF(C17="Shakes",30,0)+IF(D17="Shakes",15,0)+IF(E17="Shakes",15,0)+IF(F17="Shakes",15,0) -> 0 | I17: =IF(C17="Fries",30,0)+IF(D17="Fries",15,0)+IF(E17="Fries",15,0)+IF(F17="Fries",15,0) -> 0
B18: Round 3 | C18: NA | D18: NA | E18: NA | F18: NA | H18: =IF(C18="Shakes",30,0)+IF(D18="Shakes",15,0)+IF(E18="Shakes",15,0)+IF(F18="Shakes",15,0) -> 0 | I18: =IF(C18="Fries",30,0)+IF(D18="Fries",15,0)+IF(E18="Fries",15,0)+IF(F18="Fries",15,0) -> 0
B19: Round 4 | C19: NA | D19: NA | E19: NA | F19: NA | H19: =IF(C19="Shakes",30,0)+IF(D19="Shakes",15,0)+IF(E19="Shakes",15,0)+IF(F19="Shakes",15,0) -> 0 | I19: =IF(C19="Fries",30,0)+IF(D19="Fries",15,0)+IF(E19="Fries",15,0)+IF(F19="Fries",15,0) -> 0
B20: Round 5 | D20: NA | E20: NA | F20: NA | H20: =IF(C20="Shakes",30,0)+IF(D20="Shakes",15,0)+IF(E20="Shakes",15,0)+IF(F20="Shakes",15,0) -> 0 | I20: =IF(C20="Fries",30,0)+IF(D20="Fries",15,0)+IF(E20="Fries",15,0)+IF(F20="Fries",15,0) -> 0
B21: Round 6 | D21: NA | E21: NA | F21: NA | H21: =IF(C21="Shakes",30,0)+IF(D21="Shakes",15,0)+IF(E21="Shakes",15,0)+IF(F21="Shakes",15,0) -> 0 | I21: =IF(C21="Fries",30,0)+IF(D21="Fries",15,0)+IF(E21="Fries",15,0)+IF(F21="Fries",15,0) -> 0
G22: Block 2 Total: | H22: =SUM(H16:H21) -> 0 | I22: =SUM(I16:I21) -> 0
C24: Block 3 - The Mask we Wear
H25: Shakes | I25: Fries
D26: Big Bucket 1 | E26: Big Bucket 2
B27: Round 1 | D27: NA | E27: NA | H27: =IF(D27="Shakes",30,0)+IF(E27="Shakes",30,0) -> 0 | I27: =IF(D27="Fries",30,0)+IF(E27="Fries",30,0) -> 0
B28: Round 2 | D28: NA | E28: NA | H28: =IF(D28="Shakes",30,0)+IF(E28="Shakes",30,0) -> 0 | I28: =IF(D28="Fries",30,0)+IF(E28="Fries",30,0) -> 0
G29: Block 3 Total: | H29: =SUM(H27:H28) -> 0 | I29: =SUM(I27:I28) -> 0
C31: Block 4 - Crowd Trap
H32: Shakes | I32: Fries
B33: Nadala+ 1 | C33: Balloon Darts 1 | D33: Golden Snitch 1 | E33: Nadala+ 2 | F33: Balloon Darts 2 | G33: Golden Snitch 2
A34: Round 1 | B34: NA | C34: NA | D34: NA | E34: NA | F34: NA | G34: NA | H34: =IF(B34="Shakes",15,0)+IF(C34="Shakes",15,0)+IF(D34="Shakes",15,0)+IF(E34="Shakes",15,0)+IF(F34="Shakes",15,0)+IF(G34="Shakes",15,0) -> 0 | I34: =IF(B34="Fries",15,0)+IF(C34="Fries",15,0)+IF(D34="Fries",15,0)+IF(E34="Fries",15,0)+IF(F34="Fries",15,0)+IF(G34="Fries",15,0) -> 0
A35: Round 2 | B35: NA | C35: NA | D35: NA | E35: NA | F35: NA | G35: NA | H35: =IF(B35="Shakes",15,0)+IF(C35="Shakes",15,0)+IF(D35="Shakes",15,0)+IF(E35="Shakes",15,0)+IF(F35="Shakes",15,0)+IF(G35="Shakes",15,0) -> 0 | I35: =IF(B35="Fries",15,0)+IF(C35="Fries",15,0)+IF(D35="Fries",15,0)+IF(E35="Fries",15,0)+IF(F35="Fries",15,0)+IF(G35="Fries",15,0) -> 0
A36: Round 3 | B36: NA | C36: NA | D36: NA | E36: NA | F36: NA | G36: NA | H36: =IF(B36="Shakes",15,0)+IF(C36="Shakes",15,0)+IF(D36="Shakes",15,0)+IF(E36="Shakes",15,0)+IF(F36="Shakes",15,0)+IF(G36="Shakes",15,0) -> 0 | I36: =IF(B36="Fries",15,0)+IF(C36="Fries",15,0)+IF(D36="Fries",15,0)+IF(E36="Fries",15,0)+IF(F36="Fries",15,0)+IF(G36="Fries",15,0) -> 0
G37: Block 4 Total: | H37: =SUM(H34:H36) -> 0 | I37: =SUM(I34:I36) -> 0
G39: Blocks Total: | H39: =H11+H22+H29+H37 -> 0 | I39: =I11+I22+I29+I37 -> 0
G41: Karine Kastour | H41: =S5.1!F30 -> 0 | I41: =F5.1!F30 -> 0 | J41: Karen Tadrous
G42: Marla Isaac | H42: =S5.2!F30 -> 0 | I42: =F5.2!F30 -> 0 | J42: Shady Shahir
G43: Youssef Sadek | H43: =S5.3!F30 -> 0 | I43: =F5.3!F30 -> 0 | J43: Kirmina Sadek
G44: Jason | H44: =S6.1!F30 -> 0 | I44: =F6.1!F30 -> 0 | J44: Sherry Wael
G45: Philo Ehab | H45: =S6.2!F30 -> 0 | I45: =F6.2!F30 -> 0 | J45: Roberto
G46: Maria Ehab | H46: =S6.3!F30 -> 0 | I46: =F6.3!F30 -> 0 | J46: Ginevra
...
